Workbook

Sheet Escenarios
A1: Codigo | B1: Explicacion | C1: Tiempo (s)
A2: 013 | B2: uso de Ampolleta | C2: 600
A3: 012 | B3: Mixto (Notebook + Calefactor) con interrupciones | C3: 600
A4: 011 | B4: Mixto (Notebook + Calefactor) | C4: 600
A5: 010 | B5: Sin Carga | C5: 300
A6: 009 | B6: Calefactor | C6: 600
A7: 008 | B7: Solo Uso del Enpi | C7: 600
A8: 007 | B8: Notebook | C8: 600

Sheet 013
A1: Fecha | B1: Hora | C1: Fecha Hora | D1: Hora [UTC] | E1: U1(Min) [V] | F1: U1(Med) [V] | G1: U1(ProAct) [V] | H1: U1(Max) [V] | I1: I1(Min) [mA] | J1: I1(Med) [mA] | K1: I1(ProAct) [mA] | L1: I1(Max) [mA] | M1: f(Min) [Hz] | N1: f(ProAct) [Hz] | O1: f(Max) [Hz] | P1: P1+(Med) [W] | Q1: PF1cap+(ProAct) [] | R1: Voltaje | S1: energia_kwh | T1: Frecuencia | U1: Factor_Potencia | V1: corriente | W1: potencia_kw | X1: Error (Enp -Metrel) | Y1: Error Abs | Z1: Error Cuadrado | AA1: Error porcentual abs
A2: =+INT(D2) -> 46211 | B2: =+MOD(D2,1) -> 0.79054427 | C2: 46211.791 | D2: 46211.791 | E2: 232.54 | F2: 232.62 | G2: 232.62 | H2: 232.676 | I2: 292.889 | J2: 293.97 | K2: 293.97 | L2: 294.57 | M2: 49.976 | N2: 49.976 | O2: 49.977 | P2: 68.176 | Q2: 0.997 | R2: =+VLOOKUP($C2,Pagina!$C:$Q,10,0) -> 233.4 | S2: =+VLOOKUP($C2,Pagina!$C:$Q,11,0) -> 95.239998 | T2: =+VLOOKUP($C2,Pagina!$C:$Q,12,0) -> 49.9 | U2: =+VLOOKUP($C2,Pagina!$C:$Q,13,0) -> 1 | V2: =+VLOOKUP($C2,Pagina!$C:$Q,14,0) -> 0,270000 | W2: =+VLOOKUP($C2,Pagina!$C:$Q,15,0) -> 0,062900 | X2: =+R2-F2 -> 0.78 | Y2: =+ABS(X2) -> 0.78 | Z2: =+X2*X2 -> 0.6084 | AA2: =+(X2/F2)*100 -> 0.33531081
A3: =+INT(D3) -> 46211 | B3: =+MOD(D3,1) -> 0.79055584 | C3: 46211.791 | D3: 46211.791 | E3: 232.606 | F3: 232.652 | G3: 232.652 | H3: 232.703 | I3: 292.889 | J3: 296.37 | K3: 296.37 | L3: 301.11 | M3: 49.978 | N3: 49.98 | O3: 49.981 | P3: 68.162 | Q3: 0.989 | R3: =+VLOOKUP(C3,Pagina!C:Q,10,0) -> 233.4 | S3: =+VLOOKUP($C3,Pagina!$C:$Q,11,0) -> 95.239998 | T3: =+VLOOKUP($C3,Pagina!$C:$Q,12,0) -> 49.9 | U3: =+VLOOKUP($C3,Pagina!$C:$Q,13,0) -> 1 | V3: =+VLOOKUP($C3,Pagina!$C:$Q,14,0) -> 0,270000 | W3: =+VLOOKUP($C3,Pagina!$C:$Q,15,0) -> 0,063000 | X3: =+R3-F3 -> 0.748 | Y3: =+ABS(X3) -> 0.748 | Z3: =+X3*X3 -> 0.559504 | AA3: =+(X3/F3)*100 -> 0.32151024
A4: =+INT(D4) -> 46211 | B4: =+MOD(D4,1) -> 0.79056742 | C4: 46211.791 | D4: 46211.791 | E4: 232.535 | F4: 232.644 | G4: 232.644 | H4: 232.681 | I4: 292.552 | J4: 295.07 | K4: 295.07 | L4: 299.68 | M4: 49.98 | N4: 49.982 | O4: 49.983 | P4: 68.082 | Q4: 0.992 | R4: =+VLOOKUP(C4,Pagina!C:Q,10,0) -> 233.5 | S4: =+VLOOKUP($C4,Pagina!$C:$Q,11,0) -> 95.239998 | T4: =+VLOOKUP($C4,Pagina!$C:$Q,12,0) -> 49.9 | U4: =+VLOOKUP($C4,Pagina!$C:$Q,13,0) -> 1 | V4: =+VLOOKUP($C4,Pagina!$C:$Q,14,0) -> 0,271000 | W4: =+VLOOKUP($C4,Pagina!$C:$Q,15,0) -> 0,063200 | X4: =+R4-F4 -> 0.856 | Y4: =+ABS(X4) -> 0.856 | Z4: =+X4*X4 -> 0.732736 | AA4: =+(X4/F4)*100 -> 0.36794416
A5: =+INT(D5) -> 46211 | B5: =+MOD(D5,1) -> 0.790579 | C5: 46211.791 | D5: 46211.791 | E5: 232.637 | F5: 232.684 | G5: 232.684 | H5: 232.751 | I5: 293.268 | J5: 295.73 | K5: 295.73 | L5: 301.07 | M5: 49.983 | N5: 49.986 | O5: 49.987 | P5: 68.357 | Q5: 0.994 | R5: =+VLOOKUP(C5,Pagina!C:Q,10,0) -> 233.5 | S5: =+VLOOKUP($C5,Pagina!$C:$Q,11,0) -> 95.239998 | T5: =+VLOOKUP($C5,Pagina!$C:$Q,12,0) -> 49.9 | U5: =+VLOOKUP($C5,Pagina!$C:$Q,13,0) -> 1 | V5: =+VLOOKUP($C5,Pagina!$C:$Q,14,0) -> 0,271000 | W5: =+VLOOKUP($C5,Pagina!$C:$Q,15,0) -> 0,063200 | X5: =+R5-F5 -> 0.816 | Y5: =+ABS(X5) -> 0.816 | Z5: =+X5*X5 -> 0.665856 | AA5: =+(X5/F5)*100 -> 0.35069021
A6: =+INT(D6) -> 46211 | B6: =+MOD(D6,1) -> 0.79059058 | C6: 46211.791 | D6: 46211.791 | E6: 232.669 | F6: 232.721 | G6: 232.721 | H6: 232.763 | I6: 293.772 | J6: 294.12 | K6: 294.12 | L6: 294.49 | M6: 49.987 | N6: 49.988 | O6: 49.989 | P6: 68.297 | Q6: 0.998 | R6: =+VLOOKUP(C6,Pagina!C:Q,10,0) -> 233.5 | S6: =+VLOOKUP($C6,Pagina!$C:$Q,11,0) -> 95.239998 | T6: =+VLOOKUP($C6,Pagina!$C:$Q,12,0) -> 50 | U6: =+VLOOKUP($C6,Pagina!$C:$Q,13,0) -> 1 | V6: =+VLOOKUP($C6,Pagina!$C:$Q,14,0) -> 0,271000 | W6: =+VLOOKUP($C6,Pagina!$C:$Q,15,0) -> 0,063200 | X6: =+R6-F6 -> 0.779 | Y6: =+ABS(X6) -> 0.779 | Z6: =+X6*X6 -> 0.606841 | AA6: =+(X6/F6)*100 -> 0.33473558
A7: =+INT(D7) -> 46211 | B7: =+MOD(D7,1) -> 0.79060215 | C7: 46211.791 | D7: 46211.791 | E7: 232.651 | F7: 232.689 | G7: 232.689 | H7: 232.734 | I7: 294.15 | J7: 296.38 | K7: 296.38 | L7: 298.93 | M7: 49.99 | N7: 49.991 | O7: 49.992 | P7: 68.311 | Q7: 0.991 | R7: =+VLOOKUP(C7,Pagina!C:Q,10,0) -> 233.5 | S7: =+VLOOKUP($C7,Pagina!$C:$Q,11,0) -> 95.239998 | T7: =+VLOOKUP($C7,Pagina!$C:$Q,12,0) -> 49.9 | U7: =+VLOOKUP($C7,Pagina!$C:$Q,13,0) -> 1 | V7: =+VLOOKUP($C7,Pagina!$C:$Q,14,0) -> 0,270000 | W7: =+VLOOKUP($C7,Pagina!$C:$Q,15,0) -> 0,063000 | X7: =+R7-F7 -> 0.811 | Y7: =+ABS(X7) -> 0.811 | Z7: =+X7*X7 -> 0.657721 | AA7: =+(X7/F7)*100 -> 0.34853388
A8: =+INT(D8) -> 46211 | B8: =+MOD(D8,1) -> 0.79061373 | C8: 46211.791 | D8: 46211.791 | E8: 232.7 | F8: 232.733 | G8: 232.733 | H8: 232.777 | I8: 294.066 | J8: 299.21 | K8: 299.21 | L8: 306.75 | M8: 49.993 | N8: 49.993 | O8: 49.994 | P8: 68.382 | Q8: 0.982 | R8: =+VLOOKUP(C8,Pagina!C:Q,10,0) -> 233.5 | S8: =+VLOOKUP($C8,Pagina!$C:$Q,11,0) -> 95.239998 | T8: =+VLOOKUP($C8,Pagina!$C:$Q,12,0) -> 49.9 | U8: =+VLOOKUP($C8,Pagina!$C:$Q,13,0) -> 1 | V8: =+VLOOKUP($C8,Pagina!$C:$Q,14,0) -> 0,270000 | W8: =+VLOOKUP($C8,Pagina!$C:$Q,15,0) -> 0,062800 | X8: =+R8-F8 -> 0.767 | Y8: =+ABS(X8) -> 0.767 | Z8: =+X8*X8 -> 0.588289 | AA8: =+(X8/F8)*100 -> 0.3295622
A9: =+INT(D9) -> 46211 | B9: =+MOD(D9,1) -> 0.7906253 | C9: 46211.791 | D9: 46211.791 | E9: 232.431 | F9: 232.554 | G9: 232.554 | H9: 232.646 | I9: 295.364 | J9: 298.68 | K9: 298.68 | L9: 304.41 | M9: 49.992 | N9: 49.993 | O9: 49.994 | P9: 68.307 | Q9: 0.984 | R9: =+VLOOKUP(C9,Pagina!C:Q,10,0) -> 233.5 | S9: =+VLOOKUP($C9,Pagina!$C:$Q,11,0) -> 95.239998 | T9: =+VLOOKUP($C9,Pagina!$C:$Q,12,0) -> 50 | U9: =+VLOOKUP($C9,Pagina!$C:$Q,13,0) -> 1 | V9: =+VLOOKUP($C9,Pagina!$C:$Q,14,0) -> 0,271000 | W9: =+VLOOKUP($C9,Pagina!$C:$Q,15,0) -> 0,063100 | X9: =+R9-F9 -> 0.946 | Y9: =+ABS(X9) -> 0.946 | Z9: =+X9*X9 -> 0.894916 | AA9: =+(X9/F9)*100 -> 0.40678724
A10: =+INT(D10) -> 46211 | B10: =+MOD(D10,1) -> 0.79063687 | C10: 46211.791 | D10: 46211.791 | E10: 232.584 | F10: 232.624 | G10: 232.624 | H10: 232.716 | I10: 293.1 | J10: 294.03 | K10: 294.03 | L10: 294.57 | M10: 49.992 | N10: 49.992 | O10: 49.993 | P10: 68.228 | Q10: 0.998 | R10: =+VLOOKUP(C10,Pagina!C:Q,10,0) -> 233.5 | S10: =+VLOOKUP($C10,Pagina!$C:$Q,11,0) -> 95.239998 | T10: =+VLOOKUP($C10,Pagina!$C:$Q,12,0) -> 50 | U10: =+VLOOKUP($C10,Pagina!$C:$Q,13,0) -> 1 | V10: =+VLOOKUP($C10,Pagina!$C:$Q,14,0) -> 0,271000 | W10: =+VLOOKUP($C10,Pagina!$C:$Q,15,0) -> 0,063100 | X10: =+R10-F10 -> 0.876 | Y10: =+ABS(X10) -> 0.876 | Z10: =+X10*X10 -> 0.767376 | AA10: =+(X10/F10)*100 -> 0.37657335
A11: =+INT(D11) -> 46211 | B11: =+MOD(D11,1) -> 0.79064846 | C11: 46211.791 | D11: 46211.791 | E11: 232.637 | F11: 232.707 | G11: 232.707 | H11: 232.801 | I11: 294.024 | J11: 297.23 | K11: 297.23 | L11: 302.87 | M11: 49.992 | N11: 49.992 | O11: 49.994 | P11: 68.212 | Q11: 0.986 | R11: =+VLOOKUP(C11,Pagina!C:Q,10,0) -> 233.5 | S11: =+VLOOKUP($C11,Pagina!$C:$Q,11,0) -> 95.239998 | T11: =+VLOOKUP($C11,Pagina!$C:$Q,12,0) -> 50 | U11: =+VLOOKUP($C11,Pagina!$C:$Q,13,0) -> 1 | V11: =+VLOOKUP($C11,Pagina!$C:$Q,14,0) -> 0,271000 | W11: =+VLOOKUP($C11,Pagina!$C:$Q,15,0) -> 0,063100 | X11: =+R11-F11 -> 0.793 | Y11: =+ABS(X11) -> 0.793 | Z11: =+X11*X11 -> 0.628849 | AA11: =+(X11/F11)*100 -> 0.34077187
A12: =+INT(D12) -> 46211 | B12: =+MOD(D12,1) -> 0.79066003 | C12: 46211.791 | D12: 46211.791 | E12: 232.505 | F12: 232.643 | G12: 232.643 | H12: 232.8 | I12: 293.52 | J12: 295.58 | K12: 295.58 | L12: 296.7 | M12: 49.993 | N12: 49.995 | O12: 49.996 | P12: 68.332 | Q12: 0.994 | R12: =+VLOOKUP(C12,Pagina!C:Q,10,0) -> 233.6 | S12: =+VLOOKUP($C12,Pagina!$C:$Q,11,0) -> 95.239998 | T12: =+VLOOKUP($C12,Pagina!$C:$Q,12,0) -> 50 | U12: =+VLOOKUP($C12,Pagina!$C:$Q,13,0) -> 1 | V12: =+VLOOKUP($C12,Pagina!$C:$Q,14,0) -> 0,271000 | W12: =+VLOOKUP($C12,Pagina!$C:$Q,15,0) -> 0,063100 | X12: =+R12-F12 -> 0.957 | Y12: =+ABS(X12) -> 0.957 | Z12: =+X12*X12 -> 0.915849 | AA12: =+(X12/F12)*100 -> 0.41135989
A13: =+INT(D13) -> 46211 | B13: =+MOD(D13,1) -> 0.79067161 | C13: 46211.791 | D13: 46211.791 | E13: 232.611 | F13: 232.674 | G13: 232.674 | H13: 232.728 | I13: 295.823 | J13: 300.79 | K13: 300.79 | L13: 306.15 | M13: 49.995 | N13: 49.995 | O13: 49.996 | P13: 68.451 | Q13: 0.978 | R13: =+VLOOKUP(C13,Pagina!C:Q,10,0) -> 233.6 | S13: =+VLOOKUP($C13,Pagina!$C:$Q,11,0) -> 95.239998 | T13: =+VLOOKUP($C13,Pagina!$C:$Q,12,0) -> 50 | U13: =+VLOOKUP($C13,Pagina!$C:$Q,13,0) -> 1 | V13: =+VLOOKUP($C13,Pagina!$C:$Q,14,0) -> 0,271000 | W13: =+VLOOKUP($C13,Pagina!$C:$Q,15,0) -> 0,063100 | X13: =+R13-F13 -> 0.926 | Y13: =+ABS(X13) -> 0.926 | Z13: =+X13*X13 -> 0.857476 | AA13: =+(X13/F13)*100 -> 0.39798173
A14: =+INT(D14) -> 46211 | B14: =+MOD(D14,1) -> 0.79068318 | C14: 46211.791 | D14: 46211.791 | E14: 232.466 | F14: 232.533 | G14: 232.533 | H14: 232.641 | I14: 293.436 | J14: 298.29 | K14: 298.29 | L14: 305.38 | M14: 49.992 | N14: 49.992 | O14: 49.994 | P14: 68.131 | Q14: 0.983 | R14: =+VLOOKUP(C14,Pagina!C:Q,10,0) -> 233.6 | S14: =+VLOOKUP($C14,Pagina!$C:$Q,11,0) -> 95.239998 | T14: =+VLOOKUP($C14,Pagina!$C:$Q,12,0) -> 50 | U14: =+VLOOKUP($C14,Pagina!$C:$Q,13,0) -> 1 | V14: =+VLOOKUP($C14,Pagina!$C:$Q,14,0) -> 0,271000 | W14: =+VLOOKUP($C14,Pagina!$C:$Q,15,0) -> 0,063100 | X14: =+R14-F14 -> 1.067 | Y14: =+ABS(X14) -> 1.067 | Z14: =+X14*X14 -> 1.138489 | AA14: =+(X14/F14)*100 -> 0.4588596
... A602: =+INT(D602) -> 46211 | B602: =+MOD(D602,1) -> 0.79749049 | C602: 46211.797 | D602: 46211.797 | E602: 232.409 | F602: 232.484 | G602: 232.484 | H602: 232.54 | I602: 293.562 | J602: 294.77 | K602: 294.77 | L602: 295.74 | M602: 50.059 | N602: 50.06 | O602: 50.061 | P602: 68.18 | Q602: 0.995 | R602: =+VLOOKUP(C602,Pagina!C:Q,10,0) -> 233.5 | S602: =+VLOOKUP($C602,Pagina!$C:$Q,11,0) -> 95.25 | T602: =+VLOOKUP($C602,Pagina!$C:$Q,12,0) -> 50 | U602: =+VLOOKUP($C602,Pagina!$C:$Q,13,0) -> 1 | V602: =+VLOOKUP($C602,Pagina!$C:$Q,14,0) -> 0,271000 | W602: =+VLOOKUP($C602,Pagina!$C:$Q,15,0) -> 0,063100 | X602: =+R602-F602 -> 1.016 | Y602: =+ABS(X602) -> 1.016 | Z602: =+X602*X602 -> 1.032256 | AA602: =+(X602/F602)*100 -> 0.43701932
AA604: Voltaje
Z605: MAE | AA605: =+AVERAGE(Y1:Y602) -> 0.8718619
Z606: RMSE | AA606: =+SQRT(AVERAGE(Z2:Z602)) -> 0.89228447
Z607: MAPE | AA607: =+AVERAGE(AA2:AA602) -> 0.37490896

Sheet 012
A1: Fecha | B1: Hora | C1: Fecha Hora | D1: Hora [UTC] | E1: U1(Min) [V] | F1: U1(Med) [V] | G1: U1(ProAct) [V] | H1: U1(Max) [V] | I1: I1(Min) [A] | J1: I1(Med) [A] | K1: I1(ProAct) [A] | L1: I1(Max) [A] | M1: f(Min) [Hz] | N1: f(ProAct) [Hz] | O1: f(Max) [Hz] | P1: PF1cap+(ProAct) [] | Q1: Voltaje | R1: energia_kwh | S1: Frecuencia | T1: Factor_Potencia | U1: corriente | V1: potencia_kw | W1: Error (Enp -Metrel) | X1: Error Abs | Y1: Error Cuadrado | Z1: Error porcentual abs
A2: =+INT(D2) -> 46211 | B2: =+MOD(D2,1) -> 0.78185376 | C2: 46211.782 | D2: 46211.782 | E2: 230.189 | F2: 230.215 | G2: 230.215 | H2: 230.248 | I2: 8.54 | J2: 8.54 | K2: 8.54 | L2: 8.54 | M2: 49.988 | N2: 49.988 | O2: 49.988 | P2: 0.991 | Q2: =+VLOOKUP($C2,Pagina!$C:$Q,10,0) -> 231 | R2: =+VLOOKUP($C2,Pagina!$C:$Q,11,0) -> 95.058998 | S2: =+VLOOKUP($C2,Pagina!$C:$Q,12,0) -> 50 | T2: =+VLOOKUP($C2,Pagina!$C:$Q,13,0) -> 0,990000 | U2: =+VLOOKUP($C2,Pagina!$C:$Q,14,0) -> 8166000 | V2: =+VLOOKUP($C2,Pagina!$C:$Q,15,0) -> 1868200 | W2: =+Q2-E2 -> 0.811 | X2: =+ABS(W2) -> 0.811 | Y2: =+W2*W2 -> 0.657721 | Z2: =+(W2/E2)*100 -> 0.35231918
A3: =+INT(D3) -> 46211 | B3: =+MOD(D3,1) -> 0.78186535 | C3: 46211.782 | D3: 46211.782 | E3: 230.172 | F3: 230.221 | G3: 230.221 | H3: 230.292 | I3: 8.53 | J3: 8.53 | K3: 8.53 | L3: 8.54 | M3: 49.988 | N3: 49.988 | O3: 49.989 | P3: 0.991 | Q3: =+VLOOKUP($C3,Pagina!$C:$Q,10,0) -> 230.9 | R3: =+VLOOKUP($C3,Pagina!$C:$Q,11,0) -> 95.058998 | S3: =+VLOOKUP($C3,Pagina!$C:$Q,12,0) -> 50 | T3: =+VLOOKUP($C3,Pagina!$C:$Q,13,0) -> 0,990000 | U3: =+VLOOKUP($C3,Pagina!$C:$Q,14,0) -> 8166000 | V3: =+VLOOKUP($C3,Pagina!$C:$Q,15,0) -> 1867300 | W3: =+Q3-E3 -> 0.728 | X3: =+ABS(W3) -> 0.728 | Y3: =+W3*W3 -> 0.529984 | Z3: =+(W3/E3)*100 -> 0.31628521
A4: =+INT(D4) -> 46211 | B4: =+MOD(D4,1) -> 0.78187692 | C4: 46211.782 | D4: 46211.782 | E4: 230.172 | F4: 230.186 | G4: 230.186 | H4: 230.206 | I4: 8.53 | J4: 8.53 | K4: 8.53 | L4: 8.53 | M4: 49.988 | N4: 49.989 | O4: 49.99 | P4: 0.991 | Q4: =+VLOOKUP($C4,Pagina!$C:$Q,10,0) -> 230.9 | R4: =+VLOOKUP($C4,Pagina!$C:$Q,11,0) -> 95.059998 | S4: =+VLOOKUP($C4,Pagina!$C:$Q,12,0) -> 50 | T4: =+VLOOKUP($C4,Pagina!$C:$Q,13,0) -> 0,990000 | U4: =+VLOOKUP($C4,Pagina!$C:$Q,14,0) -> 8166000 | V4: =+VLOOKUP($C4,Pagina!$C:$Q,15,0) -> 1866800 | W4: =+Q4-E4 -> 0.728 | X4: =+ABS(W4) -> 0.728 | Y4: =+W4*W4 -> 0.529984 | Z4: =+(W4/E4)*100 -> 0.31628521
A5: =+INT(D5) -> 46211 | B5: =+MOD(D5,1) -> 0.7818885 | C5: 46211.782 | D5: 46211.782 | E5: 230.155 | F5: 230.178 | G5: 230.178 | H5: 230.205 | I5: 8.53 | J5: 8.53 | K5: 8.53 | L5: 8.53 | M5: 49.99 | N5: 49.992 | O5: 49.993 | P5: 0.991 | Q5: =+VLOOKUP($C5,Pagina!$C:$Q,10,0) -> 230.9 | R5: =+VLOOKUP($C5,Pagina!$C:$Q,11,0) -> 95.059998 | S5: =+VLOOKUP($C5,Pagina!$C:$Q,12,0) -> 50 | T5: =+VLOOKUP($C5,Pagina!$C:$Q,13,0) -> 0,990000 | U5: =+VLOOKUP($C5,Pagina!$C:$Q,14,0) -> 8164000 | V5: =+VLOOKUP($C5,Pagina!$C:$Q,15,0) -> 1866200 | W5: =+Q5-E5 -> 0.745 | X5: =+ABS(W5) -> 0.745 | Y5: =+W5*W5 -> 0.555025 | Z5: =+(W5/E5)*100 -> 0.3236949
A6: =+INT(D6) -> 46211 | B6: =+MOD(D6,1) -> 0.78190007 | C6: 46211.782 | D6: 46211.782 | E6: 230.159 | F6: 230.219 | G6: 230.219 | H6: 230.295 | I6: 8.53 | J6: 8.54 | K6: 8.54 | L6: 8.54 | M6: 49.994 | N6: 49.997 | O6: 49.999 | P6: 0.991 | Q6: =+VLOOKUP($C6,Pagina!$C:$Q,10,0) -> 230.9 | R6: =+VLOOKUP($C6,Pagina!$C:$Q,11,0) -> 95.060997 | S6: =+VLOOKUP($C6,Pagina!$C:$Q,12,0) -> 50 | T6: =+VLOOKUP($C6,Pagina!$C:$Q,13,0) -> 0,990000 | U6: =+VLOOKUP($C6,Pagina!$C:$Q,14,0) -> 8164000 | V6: =+VLOOKUP($C6,Pagina!$C:$Q,15,0) -> 1866200 | W6: =+Q6-E6 -> 0.741 | X6: =+ABS(W6) -> 0.741 | Y6: =+W6*W6 -> 0.549081 | Z6: =+(W6/E6)*100 -> 0.32195135
A7: =+INT(D7) -> 46211 | B7: =+MOD(D7,1) -> 0.78191164 | C7: 46211.782 | D7: 46211.782 | E7: 230.258 | F7: 230.291 | G7: 230.291 | H7: 230.327 | I7: 8.54 | J7: 8.54 | K7: 8.54 | L7: 8.54 | M7: 50 | N7: 50.003 | O7: 50.007 | P7: 0.991 | Q7: =+VLOOKUP($C7,Pagina!$C:$Q,10,0) -> 230.9 | R7: =+VLOOKUP($C7,Pagina!$C:$Q,11,0) -> 95.060997 | S7: =+VLOOKUP($C7,Pagina!$C:$Q,12,0) -> 50 | T7: =+VLOOKUP($C7,Pagina!$C:$Q,13,0) -> 0,990000 | U7: =+VLOOKUP($C7,Pagina!$C:$Q,14,0) -> 8161000 | V7: =+VLOOKUP($C7,Pagina!$C:$Q,15,0) -> 1866000 | W7: =+Q7-E7 -> 0.642 | X7: =+ABS(W7) -> 0.642 | Y7: =+W7*W7 -> 0.412164 | Z7: =+(W7/E7)*100 -> 0.27881767
A8: =+INT(D8) -> 46211 | B8: =+MOD(D8,1) -> 0.78192322 | C8: 46211.782 | D8: 46211.782 | E8: 230.333 | F8: 230.389 | G8: 230.389 | H8: 230.416 | I8: 8.54 | J8: 8.54 | K8: 8.54 | L8: 8.54 | M8: 50.008 | N8: 50.012 | O8: 50.016 | P8: 0.991 | Q8: =+VLOOKUP($C8,Pagina!$C:$Q,10,0) -> 231 | R8: =+VLOOKUP($C8,Pagina!$C:$Q,11,0) -> 95.061996 | S8: =+VLOOKUP($C8,Pagina!$C:$Q,12,0) -> 49.9 | T8: =+VLOOKUP($C8,Pagina!$C:$Q,13,0) -> 0,990000 | U8: =+VLOOKUP($C8,Pagina!$C:$Q,14,0) -> 8164000 | V8: =+VLOOKUP($C8,Pagina!$C:$Q,15,0) -> 1866900 | W8: =+Q8-E8 -> 0.667 | X8: =+ABS(W8) -> 0.667 | Y8: =+W8*W8 -> 0.444889 | Z8: =+(W8/E8)*100 -> 0.28958074
A9: =+INT(D9) -> 46211 | B9: =+MOD(D9,1) -> 0.78193478 | C9: 46211.782 | D9: 46211.782 | E9: 230.414 | F9: 230.44 | G9: 230.44 | H9: 230.458 | I9: 8.54 | J9: 8.54 | K9: 8.54 | L9: 8.54 | M9: 50.018 | N9: 50.022 | O9: 50.025 | P9: 0.991 | Q9: =+VLOOKUP($C9,Pagina!$C:$Q,10,0) -> 231.1 | R9: =+VLOOKUP($C9,Pagina!$C:$Q,11,0) -> 95.061996 | S9: =+VLOOKUP($C9,Pagina!$C:$Q,12,0) -> 50 | T9: =+VLOOKUP($C9,Pagina!$C:$Q,13,0) -> 0,990000 | U9: =+VLOOKUP($C9,Pagina!$C:$Q,14,0) -> 8166000 | V9: =+VLOOKUP($C9,Pagina!$C:$Q,15,0) -> 1868200 | W9: =+Q9-E9 -> 0.686 | X9: =+ABS(W9) -> 0.686 | Y9: =+W9*W9 -> 0.470596 | Z9: =+(W9/E9)*100 -> 0.29772496
A10: =+INT(D10) -> 46211 | B10: =+MOD(D10,1) -> 0.78194443 | C10: 46211.782 | D10: 46211.782 | E10: 230.441 | F10: 230.446 | G10: 230.446 | H10: 230.452 | I10: 8.53 | J10: 8.53 | K10: 8.53 | L10: 8.54 | M10: 50.028 | N10: 50.032 | O10: 50.035 | P10: 0.991 | Q10: =+VLOOKUP($C10,Pagina!$C:$Q,10,0) -> 231.1 | R10: =+VLOOKUP($C10,Pagina!$C:$Q,11,0) -> 95.063004 | S10: =+VLOOKUP($C10,Pagina!$C:$Q,12,0) -> 50 | T10: =+VLOOKUP($C10,Pagina!$C:$Q,13,0) -> 0,990000 | U10: =+VLOOKUP($C10,Pagina!$C:$Q,14,0) -> 8166000 | V10: =+VLOOKUP($C10,Pagina!$C:$Q,15,0) -> 1868200 | W10: =+Q10-E10 -> 0.659 | X10: =+ABS(W10) -> 0.659 | Y10: =+W10*W10 -> 0.434281 | Z10: =+(W10/E10)*100 -> 0.28597342
A11: =+INT(D11) -> 46211 | B11: =+MOD(D11,1) -> 0.78195831 | C11: 46211.782 | D11: 46211.782 | E11: 230.392 | F11: 230.439 | G11: 230.439 | H11: 230.48 | I11: 8.53 | J11: 8.53 | K11: 8.53 | L11: 8.54 | M11: 50.036 | N11: 50.038 | O11: 50.041 | P11: 0.991 | Q11: =+VLOOKUP($C11,Pagina!$C:$Q,10,0) -> 231 | R11: =+VLOOKUP($C11,Pagina!$C:$Q,11,0) -> 95.063004 | S11: =+VLOOKUP($C11,Pagina!$C:$Q,12,0) -> 49.9 | T11: =+VLOOKUP($C11,Pagina!$C:$Q,13,0) -> 0,990000 | U11: =+VLOOKUP($C11,Pagina!$C:$Q,14,0) -> 8165000 | V11: =+VLOOKUP($C11,Pagina!$C:$Q,15,0) -> 1867900 | W11: =+Q11-E11 -> 0.608 | X11: =+ABS(W11) -> 0.608 | Y11: =+W11*W11 -> 0.369664 | Z11: =+(W11/E11)*100 -> 0.26389805
A12: =+INT(D12) -> 46211 | B12: =+MOD(D12,1) -> 0.78196987 | C12: 46211.782 | D12: 46211.782 | E12: 230.354 | F12: 230.37 | G12: 230.37 | H12: 230.399 | I12: 8.53 | J12: 8.53 | K12: 8.53 | L12: 8.54 | M12: 50.041 | N12: 50.043 | O12: 50.046 | P12: 0.991 | Q12: =+VLOOKUP($C12,Pagina!$C:$Q,10,0) -> 231 | R12: =+VLOOKUP($C12,Pagina!$C:$Q,11,0) -> 95.064003 | S12: =+VLOOKUP($C12,Pagina!$C:$Q,12,0) -> 50 | T12: =+VLOOKUP($C12,Pagina!$C:$Q,13,0) -> 0,990000 | U12: =+VLOOKUP($C12,Pagina!$C:$Q,14,0) -> 8163000 | V12: =+VLOOKUP($C12,Pagina!$C:$Q,15,0) -> 1867300 | W12: =+Q12-E12 -> 0.646 | X12: =+ABS(W12) -> 0.646 | Y12: =+W12*W12 -> 0.417316 | Z12: =+(W12/E12)*100 -> 0.28043793
A13: =+INT(D13) -> 46211 | B13: =+MOD(D13,1) -> 0.78198145 | C13: 46211.782 | D13: 46211.782 | E13: 230.325 | F13: 230.365 | G13: 230.365 | H13: 230.396 | I13: 8.53 | J13: 8.53 | K13: 8.53 | L13: 8.54 | M13: 50.047 | N13: 50.048 | O13: 50.049 | P13: 0.991 | Q13: =+VLOOKUP($C13,Pagina!$C:$Q,10,0) -> 231 | R13: =+VLOOKUP($C13,Pagina!$C:$Q,11,0) -> 95.064003 | S13: =+VLOOKUP($C13,Pagina!$C:$Q,12,0) -> 50 | T13: =+VLOOKUP($C13,Pagina!$C:$Q,13,0) -> 0,990000 | U13: =+VLOOKUP($C13,Pagina!$C:$Q,14,0) -> 8165000 | V13: =+VLOOKUP($C13,Pagina!$C:$Q,15,0) -> 1868000 | W13: =+Q13-E13 -> 0.675 | X13: =+ABS(W13) -> 0.675 | Y13: =+W13*W13 -> 0.455625 | Z13: =+(W13/E13)*100 -> 0.29306415
... A17: =+INT(D17) -> 46211 | B17: =+MOD(D17,1) -> 0.78202769 | C17: 46211.782 | D17: 46211.782 | E17: 230.276 | F17: 230.376 | G17: 230.376 | H17: 230.654 | I17: 7.85 | J17: 8.4 | K17: 8.4 | L17: 8.53 | M17: 50.055 | N17: 50.057 | O17: 50.057 | P17: 0.991 | Q17: =+VLOOKUP($C17,Pagina!$C:$Q,10,0) -> 231.3 | R17: =+VLOOKUP($C17,Pagina!$C:$Q,11,0) -> 95.067001 | S17: =+VLOOKUP($C17,Pagina!$C:$Q,12,0) -> 50 | T17: =+VLOOKUP($C17,Pagina!$C:$Q,13,0) -> 0,990000 | U17: =+VLOOKUP($C17,Pagina!$C:$Q,14,0) -> 8165000 | V17: =+VLOOKUP($C17,Pagina!$C:$Q,15,0) -> 1869900 | W17: =+Q17-E17 -> 1.024 | X17: =+ABS(W17) -> 1.024 | Y17: =+W17*W17 -> 1.048576 | Z17: =+(W17/E17)*100 -> 0.44468377
A18: =+INT(D18) -> 46211 | B18: =+MOD(D18,1) -> 0.78203925 | C18: 46211.782 | D18: 46211.782 | E18: 232.924 | F18: 232.972 | G18: 232.972 | H18: 233.008 | I18: 0.05 | J18: 0.07 | K18: --- | L18: 0.09 | M18: 50.053 | N18: 50.055 | O18: 50.058 | P18: --- | Q18: =+VLOOKUP($C18,Pagina!$C:$Q,10,0) -> 231.3 | R18: =+VLOOKUP($C18,Pagina!$C:$Q,11,0) -> 95.067001 | S18: =+VLOOKUP($C18,Pagina!$C:$Q,12,0) -> 50 | T18: =+VLOOKUP($C18,Pagina!$C:$Q,13,0) -> 0,990000 | U18: =+VLOOKUP($C18,Pagina!$C:$Q,14,0) -> 8164000 | V18: =+VLOOKUP($C18,Pagina!$C:$Q,15,0) -> 1869600 | W18: =+Q18-E18 -> -1.624 | X18: =+ABS(W18) -> 1.624 | Y18: =+W18*W18 -> 2.637376 | Z18: =+(W18/E18)*100 -> -0.69722313
A19: =+INT(D19) -> 46211 | B19: =+MOD(D19,1) -> 0.78205081 | C19: 46211.782 | D19: 46211.782 | E19: 232.872 | F19: 232.924 | G19: 232.924 | H19: 232.974 | I19: 0.02 | J19: 0.05 | K19: --- | L19: 0.08 | M19: 50.044 | N19: 50.048 | O19: 50.052 | P19: --- | Q19: =+VLOOKUP($C19,Pagina!$C:$Q,10,0) -> 231.2 | R19: =+VLOOKUP($C19,Pagina!$C:$Q,11,0) -> 95.068001 | S19: =+VLOOKUP($C19,Pagina!$C:$Q,12,0) -> 50 | T19: =+VLOOKUP($C19,Pagina!$C:$Q,13,0) -> 0,990000 | U19: =+VLOOKUP($C19,Pagina!$C:$Q,14,0) -> 8163000 | V19: =+VLOOKUP($C19,Pagina!$C:$Q,15,0) -> 1869000 | W19: =+Q19-E19 -> -1.672 | X19: =+ABS(W19) -> 1.672 | Y19: =+W19*W19 -> 2.795584 | Z19: =+(W19/E19)*100 -> -0.717991
A20: =+INT(D20) -> 46211 | B20: =+MOD(D20,1) -> 0.78206237 | C20: 46211.782 | D20: 46211.782 | E20: 232.802 | F20: 232.835 | G20: 232.835 | H20: 232.877 | I20: 0.02 | J20: 0.03 | K20: --- | L20: 0.05 | M20: 50.034 | N20: 50.039 | O20: 50.042 | P20: --- | Q20: =+VLOOKUP($C20,Pagina!$C:$Q,10,0) -> 231.2 | R20: =+VLOOKUP($C20,Pagina!$C:$Q,11,0) -> 95.068001 | S20: =+VLOOKUP($C20,Pagina!$C:$Q,12,0) -> 50 | T20: =+VLOOKUP($C20,Pagina!$C:$Q,13,0) -> 0,990000 | U20: =+VLOOKUP($C20,Pagina!$C:$Q,14,0) -> 8163000 | V20: =+VLOOKUP($C20,Pagina!$C:$Q,15,0) -> 1869000 | W20: =+Q20-E20 -> -1.602 | X20: =+ABS(W20) -> 1.602 | Y20: =+W20*W20 -> 2.566404 | Z20: =+(W20/E20)*100 -> -0.68813842
A21: =+INT(D21) -> 46211 | B21: =+MOD(D21,1) -> 0.78207395 | C21: 46211.782 | D21: 46211.782 | E21: 232.706 | F21: 232.756 | G21: 232.756 | H21: 232.799 | I21: 0.02 | J21: 0.03 | K21: --- | L21: 0.03 | M21: 50.021 | N21: 50.026 | O21: 50.031 | P21: --- | Q21: =+VLOOKUP($C21,Pagina!$C:$Q,10,0) -> 231.2 | R21: =+VLOOKUP($C21,Pagina!$C:$Q,11,0) -> 95.069 | S21: =+VLOOKUP($C21,Pagina!$C:$Q,12,0) -> 50 | T21: =+VLOOKUP($C21,Pagina!$C:$Q,13,0) -> 0,990000 | U21: =+VLOOKUP($C21,Pagina!$C:$Q,14,0) -> 8165000 | V21: =+VLOOKUP($C21,Pagina!$C:$Q,15,0) -> 1869100 | W21: =+Q21-E21 -> -1.506 | X21: =+ABS(W21) -> 1.506 | Y21: =+W21*W21 -> 2.268036 | Z21: =+(W21/E21)*100 -> -0.64716853
A22: =+INT(D22) -> 46211 | B22: =+MOD(D22,1) -> 0.78208551 | C22: 46211.782 | D22: 46211.782 | E22: 232.708 | F22: 232.719 | G22: 232.719 | H22: 232.741 | I22: 0.02 | J22: 0.02 | K22: --- | L22: 0.03 | M22: 50.009 | N22: 50.013 | O22: 50.018 | P22: --- | Q22: =+VLOOKUP($C22,Pagina!$C:$Q,10,0) -> 231.2 | R22: =+VLOOKUP($C22,Pagina!$C:$Q,11,0) -> 95.069 | S22: =+VLOOKUP($C22,Pagina!$C:$Q,12,0) -> 50 | T22: =+VLOOKUP($C22,Pagina!$C:$Q,13,0) -> 0,990000 | U22: =+VLOOKUP($C22,Pagina!$C:$Q,14,0) -> 8163000 | V22: =+VLOOKUP($C22,Pagina!$C:$Q,15,0) -> 1869100 | W22: =+Q22-E22 -> -1.508 | X22: =+ABS(W22) -> 1.508 | Y22: =+W22*W22 -> 2.274064 | Z22: =+(W22/E22)*100 -> -0.64802241
A23: =+INT(D23) -> 46211 | B23: =+MOD(D23,1) -> 0.78209708 | C23: 46211.782 | D23: 46211.782 | E23: 232.714 | F23: 232.732 | G23: 232.732 | H23: 232.794 | I23: 0.03 | J23: 0.05 | K23: --- | L23: 0.07 | M23: 50.003 | N23: 50.005 | O23: 50.008 | P23: --- | Q23: =+VLOOKUP($C23,Pagina!$C:$Q,10,0) -> 231.2 | R23: =+VLOOKUP($C23,Pagina!$C:$Q,11,0) -> 95.07 | S23: =+VLOOKUP($C23,Pagina!$C:$Q,12,0) -> 50 | T23: =+VLOOKUP($C23,Pagina!$C:$Q,13,0) -> 0,990000 | U23: =+VLOOKUP($C23,Pagina!$C:$Q,14,0) -> 8160000 | V23: =+VLOOKUP($C23,Pagina!$C:$Q,15,0) -> 1867600 | W23: =+Q23-E23 -> -1.514 | X23: =+ABS(W23) -> 1.514 | Y23: =+W23*W23 -> 2.292196 | Z23: =+(W23/E23)*100 -> -0.65058398
A24: =+INT(D24) -> 46211 | B24: =+MOD(D24,1) -> 0.78210866 | C24: 46211.782 | D24: 46211.782 | E24: 232.732 | F24: 232.78 | G24: 232.78 | H24: 232.82 | I24: 0.02 | J24: 0.03 | K24: --- | L24: 0.05 | M24: 49.997 | N24: 49.999 | O24: 50.002 | P24: --- | Q24: =+VLOOKUP($C24,Pagina!$C:$Q,10,0) -> 232 | R24: =+VLOOKUP($C24,Pagina!$C:$Q,11,0) -> 95.07 | S24: =+VLOOKUP($C24,Pagina!$C:$Q,12,0) -> 50 | T24: =+VLOOKUP($C24,Pagina!$C:$Q,13,0) -> 1 | U24: =+VLOOKUP($C24,Pagina!$C:$Q,14,0) -> 5482000 | V24: =+VLOOKUP($C24,Pagina!$C:$Q,15,0) -> 1294800 | W24: =+Q24-E24 -> -0.732 | X24: =+ABS(W24) -> 0.732 | Y24: =+W24*W24 -> 0.535824 | Z24: =+(W24/E24)*100 -> -0.31452486
A25: =+INT(D25) -> 46211 | B25: =+MOD(D25,1) -> 0.78212023 | C25: 46211.782 | D25: 46211.782 | E25: 232.788 | F25: 232.855 | G25: 232.855 | H25: 232.934 | I25: 0.04 | J25: 0.05 | K25: --- | L25: 0.07 | M25: 49.992 | N25: 49.993 | O25: 49.995 | P25: --- | Q25: =+VLOOKUP($C25,Pagina!$C:$Q,10,0) -> 232 | R25: =+VLOOKUP($C25,Pagina!$C:$Q,11,0) -> 95.07 | S25: =+VLOOKUP($C25,Pagina!$C:$Q,12,0) -> 50 | T25: =+VLOOKUP($C25,Pagina!$C:$Q,13,0) -> 1 | U25: =+VLOOKUP($C25,Pagina!$C:$Q,14,0) -> 5482000 | V25: =+VLOOKUP($C25,Pagina!$C:$Q,15,0) -> 1294800 | W25: =+Q25-E25 -> -0.788 | X25: =+ABS(W25) -> 0.788 | Y25: =+W25*W25 -> 0.620944 | Z25: =+(W25/E25)*100 -> -0.33850542
A26: =+INT(D26) -> 46211 | B26: =+MOD(D26,1) -> 0.78213182 | C26: 46211.782 | D26: 46211.782 | E26: 232.899 | F26: 232.956 | G26: 232.956 | H26: 232.996 | I26: 0.04 | J26: 0.05 | K26: --- | L26: 0.08 | M26: 49.988 | N26: 49.989 | O26: 49.99 | P26: --- | Q26: =+VLOOKUP($C26,Pagina!$C:$Q,10,0) -> 233.8 | R26: =+VLOOKUP($C26,Pagina!$C:$Q,11,0) -> 95.07 | S26: =+VLOOKUP($C26,Pagina!$C:$Q,12,0) -> 50 | T26: =+VLOOKUP($C26,Pagina!$C:$Q,13,0) -> 0,000000 | U26: =+VLOOKUP($C26,Pagina!$C:$Q,14,0) -> 0,000000 | V26: =+VLOOKUP($C26,Pagina!$C:$Q,15,0) -> 0,000000 | W26: =+Q26-E26 -> 0.901 | X26: =+ABS(W26) -> 0.901 | Y26: =+W26*W26 -> 0.811801 | Z26: =+(W26/E26)*100 -> 0.38686297
A27: =+INT(D27) -> 46211 | B27: =+MOD(D27,1) -> 0.78214339 | C27: 46211.782 | D27: 46211.782 | E27: 232.904 | F27: 232.937 | G27: 232.937 | H27: 232.983 | I27: 0.02 | J27: 0.03 | K27: --- | L27: 0.04 | M27: 49.983 | N27: 49.985 | O27: 49.988 | P27: --- | Q27: =+VLOOKUP($C27,Pagina!$C:$Q,10,0) -> 233.7 | R27: =+VLOOKUP($C27,Pagina!$C:$Q,11,0) -> 95.07 | S27: =+VLOOKUP($C27,Pagina!$C:$Q,12,0) -> 50 | T27: =+VLOOKUP($C27,Pagina!$C:$Q,13,0) -> 0,000000 | U27: =+VLOOKUP($C27,Pagina!$C:$Q,14,0) -> 0,000000 | V27: =+VLOOKUP($C27,Pagina!$C:$Q,15,0) -> 0,000000 | W27: =+Q27-E27 -> 0.796 | X27: =+ABS(W27) -> 0.796 | Y27: =+W27*W27 -> 0.633616 | Z27: =+(W27/E27)*100 -> 0.34177172
A28: =+INT(D28) -> 46211 | B28: =+MOD(D28,1) -> 0.78215497 | C28: 46211.782 | D28: 46211.782 | E28: 232.89 | F28: 232.933 | G28: 232.933 | H28: 232.955 | I28: 0.02 | J28: 0.04 | K28: --- | L28: 0.05 | M28: 49.981 | N28: 49.982 | O28: 49.983 | P28: --- | Q28: =+VLOOKUP($C28,Pagina!$C:$Q,10,0) -> 233.6 | R28: =+VLOOKUP($C28,Pagina!$C:$Q,11,0) -> 95.07 | S28: =+VLOOKUP($C28,Pagina!$C:$Q,12,0) -> 50 | T28: =+VLOOKUP($C28,Pagina!$C:$Q,13,0) -> 0,000000 | U28: =+VLOOKUP($C28,Pagina!$C:$Q,14,0) -> 0,000000 | V28: =+VLOOKUP($C28,Pagina!$C:$Q,15,0) -> 0,000000 | W28: =+Q28-E28 -> 0.71 | X28: =+ABS(W28) -> 0.71 | Y28: =+W28*W28 -> 0.5041 | Z28: =+(W28/E28)*100 -> 0.30486496
A29: =+INT(D29) -> 46211 | B29: =+MOD(D29,1) -> 0.78216655 | C29: 46211.782 | D29: 46211.782 | E29: 232.928 | F29: 232.967 | G29: 232.967 | H29: 233.038 | I29: 0.03 | J29: 0.07 | K29: --- | L29: 0.09 | M29: 49.98 | N29: 49.98 | O29: 49.98 | P29: --- | Q29: =+VLOOKUP($C29,Pagina!$C:$Q,10,0) -> 233.6 | R29: =+VLOOKUP($C29,Pagina!$C:$Q,11,0) -> 95.07 | S29: =+VLOOKUP($C29,Pagina!$C:$Q,12,0) -> 50 | T29: =+VLOOKUP($C29,Pagina!$C:$Q,13,0) -> 0,000000 | U29: =+VLOOKUP($C29,Pagina!$C:$Q,14,0) -> 0,000000 | V29: =+VLOOKUP($C29,Pagina!$C:$Q,15,0) -> 0,000000 | W29: =+Q29-E29 -> 0.672 | X29: =+ABS(W29) -> 0.672 | Y29: =+W29*W29 -> 0.451584 | Z29: =+(W29/E29)*100 -> 0.28850117
... A31: =+INT(D31) -> 46211 | B31: =+MOD(D31,1) -> 0.7821897 | C31: 46211.782 | D31: 46211.782 | E31: 232.905 | F31: 232.948 | G31: 232.948 | H31: 233.004 | I31: 0.02 | J31: 0.03 | K31: --- | L31: 0.05 | M31: 49.977 | N31: 49.978 | O31: 49.98 | P31: --- | Q31: =+VLOOKUP($C31,Pagina!$C:$Q,10,0) -> 233.6 | R31: =+VLOOKUP($C31,Pagina!$C:$Q,11,0) -> 95.07 | S31: =+VLOOKUP($C31,Pagina!$C:$Q,12,0) -> 50 | T31: =+VLOOKUP($C31,Pagina!$C:$Q,13,0) -> 0,000000 | U31: =+VLOOKUP($C31,Pagina!$C:$Q,14,0) -> 0,000000 | V31: =+VLOOKUP($C31,Pagina!$C:$Q,15,0) -> 0,000000 | W31: =+Q31-E31 -> 0.695 | X31: =+ABS(W31) -> 0.695 | Y31: =+W31*W31 -> 0.483025 | Z31: =+(W31/E31)*100 -> 0.29840493
A32: =+INT(D32) -> 46211 | B32: =+MOD(D32,1) -> 0.78220128 | C32: 46211.782 | D32: 46211.782 | E32: 232.885 | F32: 232.932 | G32: 232.932 | H32: 232.982 | I32: 0.03 | J32: 1.2 | K32: 2.67 | L32: 2.67 | M32: 49.976 | N32: 49.977 | O32: 49.977 | P32: 0.062 | Q32: =+VLOOKUP($C32,Pagina!$C:$Q,10,0) -> 233.7 | R32: =+VLOOKUP($C32,Pagina!$C:$Q,11,0) -> 95.07 | S32: =+VLOOKUP($C32,Pagina!$C:$Q,12,0) -> 50 | T32: =+VLOOKUP($C32,Pagina!$C:$Q,13,0) -> 0,000000 | U32: =+VLOOKUP($C32,Pagina!$C:$Q,14,0) -> 0,000000 | V32: =+VLOOKUP($C32,Pagina!$C:$Q,15,0) -> 0,000000 | W32: =+Q32-E32 -> 0.815 | X32: =+ABS(W32) -> 0.815 | Y32: =+W32*W32 -> 0.664225 | Z32: =+(W32/E32)*100 -> 0.34995813
A33: =+INT(D33) -> 46211 | B33: =+MOD(D33,1) -> 0.78221286 | C33: 46211.782 | D33: 46211.782 | E33: 232.905 | F33: 232.972 | G33: 232.972 | H33: 233.046 | I33: 0.14 | J33: 0.28 | K33: 0.35 | L33: 0.4 | M33: 49.976 | N33: 49.977 | O33: 49.977 | P33: 0.441 | Q33: =+VLOOKUP($C33,Pagina!$C:$Q,10,0) -> 233.7 | R33: =+VLOOKUP($C33,Pagina!$C:$Q,11,0) -> 95.07 | S33: =+VLOOKUP($C33,Pagina!$C:$Q,12,0) -> 50 | T33: =+VLOOKUP($C33,Pagina!$C:$Q,13,0) -> 0,000000 | U33: =+VLOOKUP($C33,Pagina!$C:$Q,14,0) -> 0,000000 | V33: =+VLOOKUP($C33,Pagina!$C:$Q,15,0) -> 0,000000 | W33: =+Q33-E33 -> 0.795 | X33: =+ABS(W33) -> 0.795 | Y33: =+W33*W33 -> 0.632025 | Z33: =+(W33/E33)*100 -> 0.34134089
A34: =+INT(D34) -> 46211 | B34: =+MOD(D34,1) -> 0.78222444 | C34: 46211.782 | D34: 46211.782 | E34: 232.92 | F34: 232.996 | G34: 232.996 | H34: 233.068 | I34: 0.22 | J34: 0.3 | K34: 0.3 | L34: 0.4 | M34: 49.976 | N34: 49.976 | O34: 49.977 | P34: 0.434 | Q34: =+VLOOKUP($C34,Pagina!$C:$Q,10,0) -> 233.8 | R34: =+VLOOKUP($C34,Pagina!$C:$Q,11,0) -> 95.07 | S34: =+VLOOKUP($C34,Pagina!$C:$Q,12,0) -> 50 | T34: =+VLOOKUP($C34,Pagina!$C:$Q,13,0) -> 0,000000 | U34: =+VLOOKUP($C34,Pagina!$C:$Q,14,0) -> 0,000000 | V34: =+VLOOKUP($C34,Pagina!$C:$Q,15,0) -> 0,000000 | W34: =+Q34-E34 -> 0.88 | X34: =+ABS(W34) -> 0.88 | Y34: =+W34*W34 -> 0.7744 | Z34: =+(W34/E34)*100 -> 0.37781212
A35: =+INT(D35) -> 46211 | B35: =+MOD(D35,1) -> 0.78223602 | C35: 46211.782 | D35: 46211.782 | E35: 232.949 | F35: 232.985 | G35: 232.985 | H35: 233.053 | I35: 0.23 | J35: 0.28 | K35: 0.28 | L35: 0.33 | M35: 49.976 | N35: 49.976 | O35: 49.977 | P35: --- | Q35: =+VLOOKUP($C35,Pagina!$C:$Q,10,0) -> 233.8 | R35: =+VLOOKUP($C35,Pagina!$C:$Q,11,0) -> 95.07 | S35: =+VLOOKUP($C35,Pagina!$C:$Q,12,0) -> 49.9 | T35: =+VLOOKUP($C35,Pagina!$C:$Q,13,0) -> 0,000000 | U35: =+VLOOKUP($C35,Pagina!$C:$Q,14,0) -> 0,000000 | V35: =+VLOOKUP($C35,Pagina!$C:$Q,15,0) -> 0,000000 | W35: =+Q35-E35 -> 0.851 | X35: =+ABS(W35) -> 0.851 | Y35: =+W35*W35 -> 0.724201 | Z35: =+(W35/E35)*100 -> 0.36531601
A36: =+INT(D36) -> 46211 | B36: =+MOD(D36,1) -> 0.7822476 | C36: 46211.782 | D36: 46211.782 | E36: 232.86 | F36: 232.957 | G36: 232.957 | H36: 233.012 | I36: 0.31 | J36: 0.33 | K36: 0.33 | L36: 0.36 | M36: 49.977 | N36: 49.982 | O36: 49.987 | P36: 0.439 | Q36: =+VLOOKUP($C36,Pagina!$C:$Q,10,0) -> 233.8 | R36: =+VLOOKUP($C36,Pagina!$C:$Q,11,0) -> 95.07 | S36: =+VLOOKUP($C36,Pagina!$C:$Q,12,0) -> 49.9 | T36: =+VLOOKUP($C36,Pagina!$C:$Q,13,0) -> 0,000000 | U36: =+VLOOKUP($C36,Pagina!$C:$Q,14,0) -> 0,000000 | V36: =+VLOOKUP($C36,Pagina!$C:$Q,15,0) -> 0,000000 | W36: =+Q36-E36 -> 0.94 | X36: =+ABS(W36) -> 0.94 | Y36: =+W36*W36 -> 0.8836 | Z36: =+(W36/E36)*100 -> 0.40367603
A37: =+INT(D37) -> 46211 | B37: =+MOD(D37,1) -> 0.78225918 | C37: 46211.782 | D37: 46211.782 | E37: 232.823 | F37: 232.874 | G37: 232.874 | H37: 232.906 | I37: 0.33 | J37: 0.35 | K37: 0.35 | L37: 0.37 | M37: 49.988 | N37: 49.989 | O37: 49.991 | P37: 0.438 | Q37: =+VLOOKUP($C37,Pagina!$C:$Q,10,0) -> 233.8 | R37: =+VLOOKUP($C37,Pagina!$C:$Q,11,0) -> 95.07 | S37: =+VLOOKUP($C37,Pagina!$C:$Q,12,0) -> 50 | T37: =+VLOOKUP($C37,Pagina!$C:$Q,13,0) -> 0,000000 | U37: =+VLOOKUP($C37,Pagina!$C:$Q,14,0) -> 0,000000 | V37: =+VLOOKUP($C37,Pagina!$C:$Q,15,0) -> 0,000000 | W37: =+Q37-E37 -> 0.977 | X37: =+ABS(W37) -> 0.977 | Y37: =+W37*W37 -> 0.954529 | Z37: =+(W37/E37)*100 -> 0.41963208
A38: =+INT(D38) -> 46211 | B38: =+MOD(D38,1) -> 0.78227075 | C38: 46211.782 | D38: 46211.782 | E38: 232.095 | F38: 232.685 | G38: 232.685 | H38: 232.905 | I38: 0.35 | J38: 0.37 | K38: 0.37 | L38: 0.39 | M38: 49.993 | N38: 49.998 | O38: 50.004 | P38: 0.439 | Q38: =+VLOOKUP($C38,Pagina!$C:$Q,10,0) -> 233.8 | R38: =+VLOOKUP($C38,Pagina!$C:$Q,11,0) -> 95.07 | S38: =+VLOOKUP($C38,Pagina!$C:$Q,12,0) -> 49.9 | T38: =+VLOOKUP($C38,Pagina!$C:$Q,13,0) -> 0,000000 | U38: =+VLOOKUP($C38,Pagina!$C:$Q,14,0) -> 0,000000 | V38: =+VLOOKUP($C38,Pagina!$C:$Q,15,0) -> 0,000000 | W38: =+Q38-E38 -> 1.705 | X38: =+ABS(W38) -> 1.705 | Y38: =+W38*W38 -> 2.907025 | Z38: =+(W38/E38)*100 -> 0.73461298
A39: =+INT(D39) -> 46211 | B39: =+MOD(D39,1) -> 0.78228233 | C39: 46211.782 | D39: 46211.782 | E39: 232.654 | F39: 232.695 | G39: 232.695 | H39: 232.769 | I39: 0.38 | J39: 0.39 | K39: 0.39 | L39: 0.39 | M39: 50.003 | N39: 50.005 | O39: 50.009 | P39: 0.443 | Q39: =+VLOOKUP($C39,Pagina!$C:$Q,10,0) -> 233.8 | R39: =+VLOOKUP($C39,Pagina!$C:$Q,11,0) -> 95.07 | S39: =+VLOOKUP($C39,Pagina!$C:$Q,12,0) -> 50 | T39: =+VLOOKUP($C39,Pagina!$C:$Q,13,0) -> 0,030000 | U39: =+VLOOKUP($C39,Pagina!$C:$Q,14,0) -> 0,136000 | V39: =+VLOOKUP($C39,Pagina!$C:$Q,15,0) -> 0,001100 | W39: =+Q39-E39 -> 1.146 | X39: =+ABS(W39) -> 1.146 | Y39: =+W39*W39 -> 1.313316 | Z39: =+(W39/E39)*100 -> 0.49257696
A40: =+INT(D40) -> 46211 | B40: =+MOD(D40,1) -> 0.7822939 | C40: 46211.782 | D40: 46211.782 | E40: 232.648 | F40: 232.668 | G40: 232.668 | H40: 232.696 | I40: 0.39 | J40: 0.39 | K40: 0.39 | L40: 0.4 | M40: 50.011 | N40: 50.014 | O40: 50.016 | P40: 0.442 | Q40: =+VLOOKUP($C40,Pagina!$C:$Q,10,0) -> 233.8 | R40: =+VLOOKUP($C40,Pagina!$C:$Q,11,0) -> 95.07 | S40: =+VLOOKUP($C40,Pagina!$C:$Q,12,0) -> 49.9 | T40: =+VLOOKUP($C40,Pagina!$C:$Q,13,0) -> 0,240000 | U40: =+VLOOKUP($C40,Pagina!$C:$Q,14,0) -> 0,172000 | V40: =+VLOOKUP($C40,Pagina!$C:$Q,15,0) -> 0,009600 | W40: =+Q40-E40 -> 1.152 | X40: =+ABS(W40) -> 1.152 | Y40: =+W40*W40 -> 1.327104 | Z40: =+(W40/E40)*100 -> 0.49516867
A41: =+INT(D41) -> 46211 | B41: =+MOD(D41,1) -> 0.78230546 | C41: 46211.782 | D41: 46211.782 | E41: 232.69 | F41: 232.765 | G41: 232.765 | H41: 232.823 | I41: 0.35 | J41: 0.38 | K41: 0.38 | L41: 0.4 | M41: 50.019 | N41: 50.025 | O41: 50.03 | P41: 0.441 | Q41: =+VLOOKUP($C41,Pagina!$C:$Q,10,0) -> 233.8 | R41: =+VLOOKUP($C41,Pagina!$C:$Q,11,0) -> 95.07 | S41: =+VLOOKUP($C41,Pagina!$C:$Q,12,0) -> 50 | T41: =+VLOOKUP($C41,Pagina!$C:$Q,13,0) -> 0,400000 | U41: =+VLOOKUP($C41,Pagina!$C:$Q,14,0) -> 0,287000 | V41: =+VLOOKUP($C41,Pagina!$C:$Q,15,0) -> 0,027000 | W41: =+Q41-E41 -> 1.11 | X41: =+ABS(W41) -> 1.11 | Y41: =+W41*W41 -> 1.2321 | Z41: =+(W41/E41)*100 -> 0.47702952
A42: =+INT(D42) -> 46211 | B42: =+MOD(D42,1) -> 0.78231704 | C42: 46211.782 | D42: 46211.782 | E42: 232.742 | F42: 232.8 | G42: 232.8 | H42: 232.858 | I42: 0.37 | J42: 0.38 | K42: 0.38 | L42: 0.39 | M42: 50.032 | N42: 50.035 | O42: 50.039 | P42: 0.437 | Q42: =+VLOOKUP($C42,Pagina!$C:$Q,10,0) -> 233.8 | R42: =+VLOOKUP($C42,Pagina!$C:$Q,11,0) -> 95.07 | S42: =+VLOOKUP($C42,Pagina!$C:$Q,12,0) -> 49.9 | T42: =+VLOOKUP($C42,Pagina!$C:$Q,13,0) -> 0,390000 | U42: =+VLOOKUP($C42,Pagina!$C:$Q,14,0) -> 0,266000 | V42: =+VLOOKUP($C42,Pagina!$C:$Q,15,0) -> 0,024200 | W42: =+Q42-E42 -> 1.058 | X42: =+ABS(W42) -> 1.058 | Y42: =+W42*W42 -> 1.119364 | Z42: =+(W42/E42)*100 -> 0.45458061
A43: =+INT(D43) -> 46211 | B43: =+MOD(D43,1) -> 0.7823286 | C43: 46211.782 | D43: 46211.782 | E43: 232.627 | F43: 232.669 | G43: 232.669 | H43: 232.724 | I43: 0.38 | J43: 0.39 | K43: 0.39 | L43: 0.4 | M43: 50.041 | N43: 50.044 | O43: 50.046 | P43: 0.441 | Q43: =+VLOOKUP($C43,Pagina!$C:$Q,10,0) -> 233.8 | R43: =+VLOOKUP($C43,Pagina!$C:$Q,11,0) -> 95.07 | S43: =+VLOOKUP($C43,Pagina!$C:$Q,12,0) -> 49.9 | T43: =+VLOOKUP($C43,Pagina!$C:$Q,13,0) -> 0,390000 | U43: =+VLOOKUP($C43,Pagina!$C:$Q,14,0) -> 0,266000 | V43: =+VLOOKUP($C43,Pagina!$C:$Q,15,0) -> 0,024200 | W43: =+Q43-E43 -> 1.173 | X43: =+ABS(W43) -> 1.173 | Y43: =+W43*W43 -> 1.375929 | Z43: =+(W43/E43)*100 -> 0.50424069
A44: =+INT(D44) -> 46211 | B44: =+MOD(D44,1) -> 0.78234016 | C44: 46211.782 | D44: 46211.782 | E44: 232.619 | F44: 232.643 | G44: 232.643 | H44: 232.707 | I44: 0.39 | J44: 0.39 | K44: 0.39 | L44: 0.39 | M44: 50.046 | N44: 50.049 | O44: 50.051 | P44: 0.444 | Q44: =+VLOOKUP($C44,Pagina!$C:$Q,10,0) -> 233.8 | R44: =+VLOOKUP($C44,Pagina!$C:$Q,11,0) -> 95.07 | S44: =+VLOOKUP($C44,Pagina!$C:$Q,12,0) -> 50 | T44: =+VLOOKUP($C44,Pagina!$C:$Q,13,0) -> 0,400000 | U44: =+VLOOKUP($C44,Pagina!$C:$Q,14,0) -> 0,314000 | V44: =+VLOOKUP($C44,Pagina!$C:$Q,15,0) -> 0,029400 | W44: =+Q44-E44 -> 1.181 | X44: =+ABS(W44) -> 1.181 | Y44: =+W44*W44 -> 1.394761 | Z44: =+(W44/E44)*100 -> 0.50769714
...

Sheet 011
A1: Hora [UTC] | B1: U1(Min) [V] | C1: U1(Med) [V] | D1: U1(ProAct) [V] | E1: U1(Max) [V] | F1: I1(Min) [A] | G1: I1(Med) [A] | H1: I1(ProAct) [A] | I1: I1(Max) [A] | J1: f(Min) [Hz] | K1: f(ProAct) [Hz] | L1: f(Max) [Hz] | M1: PF1cap+(ProAct) []
A2: 46211.772 | B2: 230.958 | C2: 230.997 | D2: 230.997 | E2: 231.03 | F2: 8.534 | G2: 8.536 | H2: 8.536 | I2: 8.537 | J2: 50.071 | K2: 50.073 | L2: 50.075 | M2: 0.9907
A3: 46211.772 | B3: 230.966 | C3: 231.028 | D3: 231.028 | E3: 231.061 | F3: 8.537 | G3: 8.539 | H3: 8.539 | I3: 8.541 | J3: 50.075 | K3: 50.077 | L3: 50.078 | M3: 0.9907
A4: 46211.772 | B4: 231.035 | C4: 231.049 | D4: 231.049 | E4: 231.059 | F4: 8.538 | G4: 8.539 | H4: 8.539 | I4: 8.54 | J4: 50.078 | K4: 50.081 | L4: 50.083 | M4: 0.9907
A5: 46211.772 | B5: 231.041 | C5: 231.073 | D5: 231.073 | E5: 231.156 | F5: 8.535 | G5: 8.538 | H5: 8.538 | I5: 8.541 | J5: 50.084 | K5: 50.084 | L5: 50.086 | M5: 0.9907
A6: 46211.772 | B6: 230.831 | C6: 230.914 | D6: 230.914 | E6: 231.074 | F6: 8.525 | G6: 8.534 | H6: 8.534 | I6: 8.543 | J6: 50.086 | K6: 50.086 | L6: 50.087 | M6: 0.9907
A7: 46211.772 | B7: 231.111 | C7: 231.139 | D7: 231.139 | E7: 231.201 | F7: 8.537 | G7: 8.542 | H7: 8.542 | I7: 8.549 | J7: 50.085 | K7: 50.086 | L7: 50.086 | M7: 0.9907
A8: 46211.772 | B8: 231.038 | C8: 231.103 | D8: 231.103 | E8: 231.196 | F8: 8.536 | G8: 8.538 | H8: 8.538 | I8: 8.542 | J8: 50.084 | K8: 50.085 | L8: 50.085 | M8: 0.9907
A9: 46211.772 | B9: 231.042 | C9: 231.07 | D9: 231.07 | E9: 231.11 | F9: 8.538 | G9: 8.539 | H9: 8.539 | I9: 8.54 | J9: 50.085 | K9: 50.087 | L9: 50.089 | M9: 0.9907
A10: 46211.772 | B10: 231.128 | C10: 231.145 | D10: 231.145 | E10: 231.172 | F10: 8.539 | G10: 8.541 | H10: 8.541 | I10: 8.543 | J10: 50.09 | K10: 50.091 | L10: 50.091 | M10: 0.9907
A11: 46211.772 | B11: 231.174 | C11: 231.205 | D11: 231.205 | E11: 231.266 | F11: 8.54 | G11: 8.541 | H11: 8.541 | I11: 8.542 | J11: 50.09 | K11: 50.091 | L11: 50.092 | M11: 0.9907
A12: 46211.772 | B12: 231.19 | C12: 231.215 | D12: 231.215 | E12: 231.234 | F12: 8.537 | G12: 8.538 | H12: 8.538 | I12: 8.539 | J12: 50.092 | K12: 50.093 | L12: 50.093 | M12: 0.9907
A13: 46211.772 | B13: 231.101 | C13: 231.136 | D13: 231.136 | E13: 231.171 | F13: 8.534 | G13: 8.537 | H13: 8.537 | I13: 8.54 | J13: 50.094 | K13: 50.095 | L13: 50.095 | M13: 0.9907
... A602: 46211.779 | B602: 230.142 | C602: 230.181 | D602: 230.181 | E602: 230.236 | F602: 8.54 | G602: 8.543 | H602: 8.543 | I602: 8.544 | J602: 50.05 | K602: 50.051 | L602: 50.051 | M602: 0.9907

Sheet 010
A1: Hora [UTC] | B1: U1(Min) [V] | C1: U1(Med) [V] | D1: U1(ProAct) [V] | E1: U1(Max) [V] | F1: I1(Min) [mA] | G1: I1(Med) [mA] | H1: I1(ProAct) [mA] | I1: I1(Max) [mA] | J1: f(Min) [Hz] | K1: f(ProAct) [Hz] | L1: f(Max) [Hz] | M1: PF1cap+(ProAct) []
A2: 46211.763 | B2: 230.954 | C2: 230.976 | D2: 230.976 | E2: 230.993 | F2: 22.76 | G2: 38.09 | H2: --- | I2: 57.07 | J2: 50.05 | K2: 50.05 | L2: 50.051 | M2: ---
A3: 46211.763 | B3: 230.944 | C3: 230.969 | D3: 230.969 | E3: 230.995 | F3: 8.6 | G3: 34.77 | H3: --- | I3: 60.63 | J3: 50.049 | K3: 50.05 | L3: 50.051 | M3: ---
A4: 46211.763 | B4: 230.928 | C4: 230.953 | D4: 230.953 | E4: 230.977 | F4: 15.71 | G4: 33.32 | H4: --- | I4: 51.62 | J4: 50.048 | K4: 50.048 | L4: 50.049 | M4: ---
A5: 46211.763 | B5: 231.003 | C5: 231.061 | D5: 231.061 | E5: 231.094 | F5: 21.07 | G5: 39.55 | H5: --- | I5: 55.98 | J5: 50.048 | K5: 50.049 | L5: 50.049 | M5: ---
A6: 46211.763 | B6: 231.074 | C6: 231.101 | D6: 231.101 | E6: 231.144 | F6: 11.11 | G6: 17.35 | H6: --- | I6: 31.02 | J6: 50.049 | K6: 50.051 | L6: 50.053 | M6: ---
A7: 46211.763 | B7: 231.115 | C7: 231.173 | D7: 231.173 | E7: 231.244 | F7: 11.11 | G7: 31.02 | H7: --- | I7: 41.85 | J7: 50.054 | K7: 50.059 | L7: 50.062 | M7: ---
A8: 46211.763 | B8: 231.112 | C8: 231.195 | D8: 231.195 | E8: 231.282 | F8: 21.65 | G8: 67.71 | H8: --- | I8: 110.84 | J8: 50.064 | K8: 50.068 | L8: 50.073 | M8: ---
A9: 46211.763 | B9: 231.202 | C9: 231.281 | D9: 231.281 | E9: 231.322 | F9: 28.1 | G9: 62.67 | H9: --- | I9: 80.4 | J9: 50.075 | K9: 50.078 | L9: 50.08 | M9: ---
A10: 46211.763 | B10: 231.274 | C10: 231.314 | D10: 231.314 | E10: 231.332 | F10: 11.11 | G10: 36.7 | H10: --- | I10: 56.42 | J10: 50.081 | K10: 50.083 | L10: 50.085 | M10: ---
A11: 46211.763 | B11: 231.306 | C11: 231.332 | D11: 231.332 | E11: 231.35 | F11: 11.11 | G11: 26 | H11: --- | I11: 35.82 | J11: 50.086 | K11: 50.088 | L11: 50.09 | M11: ---
A12: 46211.764 | B12: 231.329 | C12: 231.397 | D12: 231.397 | E12: 231.444 | F12: 16.47 | G12: 37.76 | H12: --- | I12: 55.76 | J12: 50.09 | K12: 50.092 | L12: 50.094 | M12: ---
A13: 46211.764 | B13: 231.424 | C13: 231.457 | D13: 231.457 | E13: 231.488 | F13: 18.59 | G13: 52.61 | H13: --- | I13: 95.03 | J13: 50.094 | K13: 50.096 | L13: 50.097 | M13: ---
... A302: 46211.767 | B302: 231.375 | C302: 231.398 | D302: 231.398 | E302: 231.434 | F302: 14.05 | G302: 29.72 | H302: --- | I302: 46.6 | J302: 50.04 | K302: 50.042 | L302: 50.044 | M302: ---

Sheet 009
A1: Hora [UTC] | B1: U1(Min) [V] | C1: U1(Med) [V] | D1: U1(ProAct) [V] | E1: U1(Max) [V] | F1: I1(Min) [A] | G1: I1(Med) [A] | H1: I1(ProAct) [A] | I1: I1(Max) [A] | J1: f(Min) [Hz] | K1: f(ProAct) [Hz] | L1: f(Max) [Hz] | M1: PF1cap+(ProAct) []
A2: 46211.744 | B2: 222.841 | C2: 222.913 | D2: 222.913 | E2: 222.968 | F2: 8.164 | G2: 8.17 | H2: 8.17 | I2: 8.173 | J2: 49.915 | K2: 49.916 | L2: 49.917 | M2: 0.9933
A3: 46211.744 | B3: 222.876 | C3: 222.898 | D3: 222.898 | E3: 222.916 | F3: 8.163 | G3: 8.165 | H3: 8.165 | I3: 8.166 | J3: 49.915 | K3: 49.916 | L3: 49.917 | M3: 0.9933
A4: 46211.744 | B4: 222.863 | C4: 222.947 | D4: 222.947 | E4: 223.014 | F4: 8.161 | G4: 8.162 | H4: 8.162 | I4: 8.164 | J4: 49.917 | K4: 49.918 | L4: 49.919 | M4: 0.9933
A5: 46211.744 | B5: 222.96 | C5: 223.009 | D5: 223.009 | E5: 223.044 | F5: 8.156 | G5: 8.158 | H5: 8.158 | I5: 8.16 | J5: 49.92 | K5: 49.921 | L5: 49.923 | M5: 0.9933
A6: 46211.744 | B6: 223.035 | C6: 223.066 | D6: 223.066 | E6: 223.104 | F6: 8.154 | G6: 8.156 | H6: 8.156 | I6: 8.157 | J6: 49.925 | K6: 49.927 | L6: 49.928 | M6: 0.9933
A7: 46211.744 | B7: 223.032 | C7: 223.073 | D7: 223.073 | E7: 223.117 | F7: 8.151 | G7: 8.154 | H7: 8.154 | I7: 8.158 | J7: 49.929 | K7: 49.929 | L7: 49.93 | M7: 0.9933
A8: 46211.744 | B8: 223.003 | C8: 223.062 | D8: 223.062 | E8: 223.114 | F8: 8.15 | G8: 8.155 | H8: 8.155 | I8: 8.157 | J8: 49.929 | K8: 49.93 | L8: 49.93 | M8: 0.9933
A9: 46211.744 | B9: 222.992 | C9: 223.074 | D9: 223.074 | E9: 223.173 | F9: 8.153 | G9: 8.157 | H9: 8.157 | I9: 8.162 | J9: 49.929 | K9: 49.93 | L9: 49.93 | M9: 0.9932
A10: 46211.744 | B10: 223.03 | C10: 223.081 | D10: 223.081 | E10: 223.12 | F10: 8.15 | G10: 8.152 | H10: 8.152 | I10: 8.154 | J10: 49.93 | K10: 49.931 | L10: 49.932 | M10: 0.9932
A11: 46211.744 | B11: 223.063 | C11: 223.129 | D11: 223.129 | E11: 223.19 | F11: 8.148 | G11: 8.152 | H11: 8.152 | I11: 8.154 | J11: 49.932 | K11: 49.934 | L11: 49.936 | M11: 0.9933
A12: 46211.744 | B12: 223.097 | C12: 223.137 | D12: 223.137 | E12: 223.199 | F12: 8.144 | G12: 8.148 | H12: 8.148 | I12: 8.151 | J12: 49.937 | K12: 49.939 | L12: 49.94 | M12: 0.9932
A13: 46211.744 | B13: 223.034 | C13: 223.08 | D13: 223.08 | E13: 223.137 | F13: 8.14 | G13: 8.142 | H13: 8.142 | I13: 8.145 | J13: 49.939 | K13: 49.94 | L13: 49.94 | M13: 0.9932
... A603: 46211.751 | B603: 221.372 | C603: 221.428 | D603: 221.428 | E603: 221.484 | F603: 8.137 | G603: 8.14 | H603: 8.14 | I603: 8.144 | J603: 50.007 | K603: 50.007 | L603: 50.007 | M603: 0.9934

Sheet 008
A1: Hora [UTC] | B1: U1(Min) [V] | C1: U1(Med) [V] | D1: U1(ProAct) [V] | E1: U1(Max) [V] | F1: I1(Min) [mA] | G1: I1(Med) [mA] | H1: I1(ProAct) [mA] | I1: I1(Max) [mA] | J1: f(Min) [Hz] | K1: f(ProAct) [Hz] | L1: f(Max) [Hz] | M1: PF1cap+(ProAct) []
A2: 46211.703 | B2: 226.344 | C2: 226.451 | D2: 226.451 | E2: 226.564 | F2: 17.91 | G2: 30.13 | H2: --- | I2: 36.16 | J2: 49.936 | K2: 49.938 | L2: 49.94 | M2: ---
A3: 46211.703 | B3: 226.488 | C3: 226.504 | D3: 226.504 | E3: 226.539 | F3: 17.91 | G3: 30.3 | H3: --- | I3: 51.86 | J3: 49.942 | K3: 49.944 | L3: 49.947 | M3: ---
A4: 46211.703 | B4: 226.437 | C4: 226.462 | D4: 226.462 | E4: 226.496 | F4: 24.33 | G4: 46.96 | H4: --- | I4: 70.77 | J4: 49.949 | K4: 49.952 | L4: 49.954 | M4: ---
A5: 46211.703 | B5: 226.408 | C5: 226.446 | D5: 226.446 | E5: 226.479 | F5: 26.75 | G5: 40.29 | H5: --- | I5: 56.2 | J5: 49.955 | K5: 49.957 | L5: 49.958 | M5: ---
A6: 46211.703 | B6: 225.957 | C6: 226.223 | D6: 226.223 | E6: 226.448 | F6: 25.81 | G6: 32.57 | H6: --- | I6: 44.7 | J6: 49.95 | K6: 49.953 | L6: 49.956 | M6: ---
A7: 46211.703 | B7: 226.203 | C7: 226.246 | D7: 226.246 | E7: 226.264 | F7: 19.24 | G7: 25.71 | H7: --- | I7: 36.16 | J7: 49.948 | K7: 49.949 | L7: 49.95 | M7: ---
A8: 46211.703 | B8: 226.252 | C8: 226.284 | D8: 226.284 | E8: 226.322 | F8: 19.24 | G8: 35.89 | H8: --- | I8: 53.96 | J8: 49.947 | K8: 49.948 | L8: 49.95 | M8: ---
A9: 46211.703 | B9: 226.293 | C9: 226.357 | D9: 226.357 | E9: 226.432 | F9: 19.87 | G9: 24.64 | H9: --- | I9: 29.8 | J9: 49.95 | K9: 49.951 | L9: 49.952 | M9: ---
A10: 46211.703 | B10: 226.328 | C10: 226.39 | D10: 226.39 | E10: 226.453 | F10: 17.91 | G10: 36.36 | H10: --- | I10: 62.04 | J10: 49.952 | K10: 49.953 | L10: 49.954 | M10: ---
A11: 46211.703 | B11: 226.218 | C11: 226.276 | D11: 226.276 | E11: 226.35 | F11: 17.21 | G11: 28.79 | H11: --- | I11: 43.3 | J11: 49.949 | K11: 49.952 | L11: 49.954 | M11: ---
A12: 46211.703 | B12: 226.145 | C12: 226.188 | D12: 226.188 | E12: 226.277 | F12: 26.75 | G12: 58.43 | H12: --- | I12: 77.75 | J12: 49.943 | K12: 49.945 | L12: 49.948 | M12: ---
A13: 46211.703 | B13: 226.211 | C13: 226.258 | D13: 226.258 | E13: 226.299 | F13: 17.21 | G13: 39.24 | H13: --- | I13: 60.83 | J13: 49.938 | K13: 49.941 | L13: 49.943 | M13: ---
... A376: 46211.707 | B376: 226.829 | C376: 226.843 | D376: 226.843 | E376: 226.851 | F376: 25.81 | G376: 48.11 | H376: --- | I376: 59.4 | J376: 49.909 | K376: 49.911 | L376: 49.914 | M376: ---
A377: 46211.707 | B377: 226.787 | C377: 226.848 | D377: 226.848 | E377: 226.899 | F377: 35.12 | G377: 95.7 | H377: 163.688 | I377: 163.69 | J377: 49.906 | K377: 49.907 | L377: 49.908 | M377: ---
A378: 46211.707 | B378: 226.755 | C378: 226.802 | D378: 226.802 | E378: 226.883 | F378: 42.73 | G378: 73.34 | H378: --- | I378: 128.28 | J378: 49.896 | K378: 49.901 | L378: 49.904 | M378: ---
A379: 46211.707 | B379: 226.714 | C379: 226.748 | D379: 226.748 | E379: 226.822 | F379: 30.62 | G379: 65.44 | H379: --- | I379: 105.6 | J379: 49.891 | K379: 49.893 | L379: 49.894 | M379: ---
A380: 46211.707 | B380: 226.816 | C380: 226.879 | D380: 226.879 | E380: 226.915 | F380: 27.66 | G380: 94.64 | H380: 155.969 | I380: 155.97 | J380: 49.891 | K380: 49.892 | L380: 49.893 | M380: ---
A381: 46211.707 | B381: 226.939 | C381: 227.03 | D381: 227.03 | E381: 227.125 | F381: 74.51 | G381: 113.44 | H381: 158.636 | I381: 158.64 | J381: 49.893 | K381: 49.896 | L381: 49.898 | M381: ---
A382: 46211.707 | B382: 227.117 | C382: 227.174 | D382: 227.174 | E382: 227.217 | F382: 28.96 | G382: 42.26 | H382: --- | I382: 58.35 | J382: 49.899 | K382: 49.9 | L382: 49.902 | M382: ---
A383: 46211.707 | B383: 227.035 | C383: 227.135 | D383: 227.135 | E383: 227.241 | F383: 24.84 | G383: 65.6 | H383: --- | I383: 109.28 | J383: 49.902 | K383: 49.902 | L383: 49.903 | M383: ---
A384: 46211.707 | B384: 226.99 | C384: 227.063 | D384: 227.063 | E384: 227.112 | F384: 25.81 | G384: 39.17 | H384: --- | I384: 56.85 | J384: 49.899 | K384: 49.9 | L384: 49.903 | M384: ---
A385: 46211.707 | B385: 226.913 | C385: 226.972 | D385: 226.972 | E385: 227.026 | F385: 31.8 | G385: 55.67 | H385: --- | I385: 70.25 | J385: 49.893 | K385: 49.896 | L385: 49.899 | M385: ---
A386: 46211.707 | B386: 226.838 | C386: 226.872 | D386: 226.872 | E386: 226.915 | F386: 27.66 | G386: 44.48 | H386: --- | I386: 56.63 | J386: 49.886 | K386: 49.888 | L386: 49.891 | M386: ---
A387: 46211.707 | B387: 226.904 | C387: 227.075 | D387: 227.075 | E387: 227.205 | F387: 20.48 | G387: 37.37 | H387: --- | I387: 52.57 | J387: 49.885 | K387: 49.886 | L387: 49.887 | M387: ---
A388: 46211.707 | B388: 227.132 | C388: 227.176 | D388: 227.176 | E388: 227.211 | F388: 17.91 | G388: 28.88 | H388: --- | I388: 43.02 | J388: 49.888 | K388: 49.89 | L388: 49.892 | M388: ---
A389: 46211.707 | B389: 226.975 | C389: 227.057 | D389: 227.057 | E389: 227.145 | F389: 17.91 | G389: 26.38 | H389: --- | I389: 33.69 | J389: 49.892 | K389: 49.893 | L389: 49.894 | M389: ---
A390: 46211.707 | B390: 226.885 | C390: 226.925 | D390: 226.925 | E390: 226.966 | F390: 22.76 | G390: 48.82 | H390: --- | I390: 63.22 | J390: 49.893 | K390: 49.893 | L390: 49.894 | M390: ---
A391: 46211.707 | B391: 226.861 | C391: 226.945 | D391: 226.945 | E391: 227.05 | F391: 18.59 | G391: 25.23 | H391: --- | I391: 30.21 | J391: 49.89 | K391: 49.891 | L391: 49.892 | M391: ---
A392: 46211.707 | B392: 226.923 | C392: 227.024 | D392: 227.024 | E392: 227.098 | F392: 40.66 | G392: 58.39 | H392: --- | I392: 78.69 | J392: 49.891 | K392: 49.892 | L392: 49.892 | M392: ---
A393: 46211.707 | B393: 226.813 | C393: 226.877 | D393: 226.877 | E393: 226.925 | F393: 30.62 | G393: 52.05 | H393: --- | I393: 70.25 | J393: 49.884 | K393: 49.887 | L393: 49.889 | M393: ---
... A603: 46211.71 | B603: 227.227 | C603: 227.293 | D603: 227.293 | E603: 227.359 | F603: 21.65 | G603: 56.37 | H603: --- | I603: 74.67 | J603: 50.122 | K603: 50.125 | L603: 50.127 | M603: ---

Sheet 007
A1: Hora [UTC] | B1: U1(Min) [V] | C1: U1(Med) [V] | D1: U1(ProAct) [V] | E1: U1(Max) [V] | F1: I1(Min) [mA] | G1: I1(Med) [mA] | H1: I1(ProAct) [mA] | I1: I1(Max) [mA] | J1: f(Min) [Hz] | K1: f(ProAct) [Hz] | L1: f(Max) [Hz] | M1: PF1cap+(ProAct) []
A2: 46211.686 | B2: 226.078 | C2: 226.116 | D2: 226.116 | E2: 226.165 | F2: 152.37 | G2: 157.7 | H2: 157.7 | I2: 166.67 | J2: 50.067 | K2: 50.068 | L2: 50.069 | M2: ---
A3: 46211.686 | B3: 226.133 | C3: 226.166 | D3: 226.166 | E3: 226.224 | F3: 151.8 | G3: 156.9 | H3: 156.9 | I3: 164.36 | J3: 50.069 | K3: 50.069 | L3: 50.07 | M3: ---
A4: 46211.686 | B4: 226.089 | C4: 226.185 | D4: 226.185 | E4: 226.263 | F4: 154.54 | G4: 158.71 | H4: 158.71 | I4: 162.93 | J4: 50.071 | K4: 50.072 | L4: 50.074 | M4: ---
A5: 46211.686 | B5: 226.171 | C5: 226.188 | D5: 226.188 | E5: 226.212 | F5: 150.9 | G5: 156.06 | H5: 156.06 | I5: 162.33 | J5: 50.074 | K5: 50.077 | L5: 50.079 | M5: ---
A6: 46211.686 | B6: 226.166 | C6: 226.197 | D6: 226.197 | E6: 226.239 | F6: 150.33 | G6: 153.9 | H6: 153.9 | I6: 157.46 | J6: 50.078 | K6: 50.08 | L6: 50.082 | M6: ---
A7: 46211.686 | B7: 226.169 | C7: 226.228 | D7: 226.228 | E7: 226.266 | F7: 149.34 | G7: 154.35 | H7: 155.57 | I7: 158.09 | J7: 50.084 | K7: 50.087 | L7: 50.089 | M7: ---
A8: 46211.686 | B8: 226.102 | C8: 226.195 | D8: 226.195 | E8: 226.253 | F8: 153.34 | G8: 157.28 | H8: 157.28 | I8: 160.34 | J8: 50.089 | K8: 50.09 | L8: 50.092 | M8: ---
A9: 46211.686 | B9: 226.079 | C9: 226.143 | D9: 226.143 | E9: 226.216 | F9: 150.41 | G9: 160.55 | H9: 160.55 | I9: 171.99 | J9: 50.094 | K9: 50.095 | L9: 50.096 | M9: ---
A10: 46211.686 | B10: 226.089 | C10: 226.139 | D10: 226.139 | E10: 226.192 | F10: 153.18 | G10: 159.09 | H10: 159.09 | I10: 168.37 | J10: 50.095 | K10: 50.097 | L10: 50.098 | M10: ---
A11: 46211.686 | B11: 226.094 | C11: 226.123 | D11: 226.123 | E11: 226.168 | F11: 147.51 | G11: 153.11 | H11: 156.65 | I11: 163.61 | J11: 50.098 | K11: 50.099 | L11: 50.1 | M11: ---
A12: 46211.686 | B12: 226.085 | C12: 226.133 | D12: 226.133 | E12: 226.176 | F12: 158.79 | G12: 165.2 | H12: 165.2 | I12: 170.48 | J12: 50.101 | K12: 50.101 | L12: 50.102 | M12: ---
A13: 46211.686 | B13: 226.057 | C13: 226.129 | D13: 226.129 | E13: 226.173 | F13: 147.77 | G13: 160.84 | H13: 163.95 | I13: 171.85 | J13: 50.101 | K13: 50.102 | L13: 50.102 | M13: ---
... A99: 46211.687 | B99: 226.145 | C99: 226.246 | D99: 226.246 | E99: 226.318 | F99: 153.66 | G99: 161.47 | H99: 161.47 | I99: 170.7 | J99: 50.082 | K99: 50.084 | L99: 50.085 | M99: ---
A100: 46211.687 | B100: 226.098 | C100: 226.135 | D100: 226.135 | E100: 226.171 | F100: 252.3 | G100: 295.42 | H100: 295.42 | I100: 343.81 | J100: 50.078 | K100: 50.079 | L100: 50.081 | M100: 0.484
A101: 46211.687 | B101: 226.143 | C101: 226.214 | D101: 226.214 | E101: 226.308 | F101: 143.1 | G101: 185.52 | H101: 194.68 | I101: 268.41 | J101: 50.074 | K101: 50.076 | L101: 50.078 | M101: ---
A102: 46211.687 | B102: 226.264 | C102: 226.298 | D102: 226.298 | E102: 226.348 | F102: 142.93 | G102: 151.17 | H102: 155.52 | I102: 163.08 | J102: 50.073 | K102: 50.073 | L102: 50.074 | M102: ---
A103: 46211.687 | B103: 226.163 | C103: 226.223 | D103: 226.223 | E103: 226.271 | F103: 167.85 | G103: 275.37 | H103: 275.37 | I103: 344.85 | J103: 50.072 | K103: 50.072 | L103: 50.073 | M103: 0.474
A104: 46211.687 | B104: 226.109 | C104: 226.203 | D104: 226.203 | E104: 226.238 | F104: 142.24 | G104: 227.92 | H104: 312.75 | I104: 350.52 | J104: 50.07 | K104: 50.072 | L104: 50.072 | M104: 0.474
A105: 46211.687 | B105: 226.231 | C105: 226.28 | D105: 226.28 | E105: 226.368 | F105: 136.03 | G105: 143.99 | H105: 154.06 | I105: 154.06 | J105: 50.071 | K105: 50.071 | L105: 50.072 | M105: ---
A106: 46211.687 | B106: 226.275 | C106: 226.323 | D106: 226.323 | E106: 226.365 | F106: 132.45 | G106: 137.9 | H106: --- | I106: 142.32 | J106: 50.07 | K106: 50.07 | L106: 50.072 | M106: ---
A107: 46211.687 | B107: 226.199 | C107: 226.287 | D107: 226.287 | E107: 226.368 | F107: 129.05 | G107: 132.22 | H107: --- | I107: 135.3 | J107: 50.061 | K107: 50.065 | L107: 50.068 | M107: ---
A108: 46211.687 | B108: 226.252 | C108: 226.299 | D108: 226.299 | E108: 226.37 | F108: 132.63 | G108: 136.63 | H108: --- | I108: 140.23 | J108: 50.06 | K108: 50.06 | L108: 50.061 | M108: ---
A109: 46211.687 | B109: 226.249 | C109: 226.322 | D109: 226.322 | E109: 226.368 | F109: 135.67 | G109: 136.86 | H109: --- | I109: 137.92 | J109: 50.058 | K109: 50.059 | L109: 50.06 | M109: ---
A110: 46211.687 | B110: 226.293 | C110: 226.346 | D110: 226.346 | E110: 226.419 | F110: 137.02 | G110: 141.12 | H110: --- | I110: 146.76 | J110: 50.059 | K110: 50.059 | L110: 50.06 | M110: ---
A111: 46211.687 | B111: 226.273 | C111: 226.303 | D111: 226.303 | E111: 226.343 | F111: 128.28 | G111: 139.98 | H111: 153.34 | I111: 153.34 | J111: 50.056 | K111: 50.057 | L111: 50.059 | M111: ---
A112: 46211.687 | B112: 226.126 | C112: 226.214 | D112: 226.214 | E112: 226.278 | F112: 142.75 | G112: 156.05 | H112: 168.7 | I112: 184.99 | J112: 50.052 | K112: 50.053 | L112: 50.055 | M112: ---
A113: 46211.687 | B113: 226.166 | C113: 226.214 | D113: 226.214 | E113: 226.269 | F113: 133.74 | G113: 143.08 | H113: 160.18 | I113: 160.18 | J113: 50.05 | K113: 50.05 | L113: 50.051 | M113: ---
A114: 46211.687 | B114: 226.085 | C114: 226.208 | D114: 226.208 | E114: 226.253 | F114: 128.28 | G114: 146.95 | H114: 168.41 | I114: 180.53 | J114: 50.047 | K114: 50.048 | L114: 50.048 | M114: ---
A115: 46211.687 | B115: 226.153 | C115: 226.204 | D115: 226.204 | E115: 226.279 | F115: 140.75 | G115: 250.57 | H115: 271.16 | I115: 346.99 | J115: 50.048 | K115: 50.049 | L115: 50.049 | M115: 0.482
A116: 46211.687 | B116: 226.03 | C116: 226.111 | D116: 226.111 | E116: 226.154 | F116: 148.68 | G116: 267.12 | H116: 289.24 | I116: 346.7 | J116: 50.048 | K116: 50.048 | L116: 50.048 | M116: 0.482
A117: 46211.687 | B117: 226.119 | C117: 226.367 | D117: 226.367 | E117: 226.493 | F117: 132.35 | G117: 145.85 | H117: 161.41 | I117: 167.93 | J117: 50.048 | K117: 50.053 | L117: 50.058 | M117: ---
A118: 46211.687 | B118: 226.501 | C118: 226.536 | D118: 226.536 | E118: 226.575 | F118: 141.98 | G118: 176.65 | H118: 184.3 | I118: 238.01 | J118: 50.059 | K118: 50.062 | L118: 50.066 | M118: ---
A119: 46211.687 | B119: 226.505 | C119: 226.557 | D119: 226.557 | E119: 226.605 | F119: 148.1 | G119: 190.93 | H119: 200.21 | I119: 226.42 | J119: 50.068 | K119: 50.073 | L119: 50.077 | M119: ---
A120: 46211.687 | B120: 226.482 | C120: 226.513 | D120: 226.513 | E120: 226.562 | F120: 203.16 | G120: 228.55 | H120: 228.55 | I120: 243.99 | J120: 50.08 | K120: 50.085 | L120: 50.091 | M120: ---
A121: 46211.687 | B121: 226.496 | C121: 226.538 | D121: 226.538 | E121: 226.597 | F121: 143.27 | G121: 179.48 | H121: 187.44 | I121: 222.69 | J121: 50.093 | K121: 50.097 | L121: 50.101 | M121: ---
A122: 46211.687 | B122: 226.491 | C122: 226.546 | D122: 226.546 | E122: 226.624 | F122: 232.18 | G122: 234.54 | H122: 234.54 | I122: 238.57 | J122: 50.103 | K122: 50.107 | L122: 50.111 | M122: ---
A123: 46211.687 | B123: 226.494 | C123: 226.519 | D123: 226.519 | E123: 226.531 | F123: 135.03 | G123: 174.84 | H123: 217.53 | I123: 231.22 | J123: 50.111 | K123: 50.113 | L123: 50.115 | M123: ---
A124: 46211.687 | B124: 226.454 | C124: 226.497 | D124: 226.497 | E124: 226.533 | F124: 156.52 | G124: 202.98 | H124: 202.98 | I124: 223.74 | J124: 50.115 | K124: 50.117 | L124: 50.119 | M124: ---
A125: 46211.687 | B125: 226.44 | C125: 226.501 | D125: 226.501 | E125: 226.552 | F125: 202.62 | G125: 211.19 | H125: 211.19 | I125: 218.16 | J125: 50.121 | K125: 50.123 | L125: 50.125 | M125: ---
...

Sheet Pagina
A1: id_lectura | B1: codigo_medidor | C1: fecha_hora | D1: voltaje | E1: corriente | F1: potencia_kw | G1: energia_kwh | H1: payload_raw | I1: created_at | J1: frecuencia | K1: factor_potencia | L1: Voltaje | M1: energia_kwh | N1: Frecuencia | O1: Factor_Potencia | P1: corriente | Q1: potencia_kw
A2: 55882 | B2: ARDUINO_001 | C2: 46211.676 | D2: 227100000 | E2: 0.168000 | F2: 0.017300 | G2: 94147003 | H2: {"modo":"lote","codigo_medidor":"ARDUINO_001","fecha_hora":"2026-07-08 16:14:05","voltaje":227.099999999999994315658113919198513031005859375,"corriente":0.1680000000000000104360964314764714799821376800537109375,"potencia_kw":0.0172999999999999994060306818255412508733570575714111328125,"energia_kwh":94.1470029999999979963831719942390918731689453125,"frecuencia":50,"factor_potencia":0.450000000000000011102230246251565404236316680908203125,"duracion_medicion_ms":62,"ip":"158.170.24.54"} | I2: 46211.635 | J2: 50000000 | K2: 0.450000 | L2: =+D2/1000000 -> 227.1 | M2: =+G2/1000000 -> 94.147003 | N2: =+J2/1000000 -> 50 | O2: =SUBSTITUTE(K2,".",",") -> 0,450000 | P2: =SUBSTITUTE(E2,".",",") -> 0,168000 | Q2: =SUBSTITUTE(F2,".",",") -> 0,017300
